<?xml version='1.0'?>
<sdf version='1.7'>
  <model name='boat_0'>
    <!-- The trampoline frame is the base link that everything else is attached to -->
    <self_collide>1</self_collide>
    <link name='base_link'>
      <pose>0 0 0 0 -0 0</pose>
       <inertial>
        <pose>2.5 1.45 0.6 0 0 3.14</pose>
        <mass>180</mass>
        <inertia>
          <ixx>120</ixx>
          <ixy>0</ixy>
          <iyy>393</iyy>
          <iyz>0</iyz>
          <izz>446</izz>
        </inertia>
      </inertial>
      <self_collide>0</self_collide>
      <enable_wind>1</enable_wind>
      <kinematic>0</kinematic>
      <gravity>1</gravity>
      <!-- Tramp visuals -->
      <visual name="scaled_trampoline_visual">
      	<pose>1.776 0 0.85 1.57 -0 0</pose>
        <geometry>
          <mesh>
            <uri>meshes/trampoline.dae</uri>
          </mesh>
        </geometry>
      </visual>
      <visual name="brain_box_visual">
      	<pose>2.876 0.75 1.1 1.57 -0 -1.57</pose>
        <geometry>
          <mesh>
            <uri>meshes/brain_box.dae</uri>
          </mesh>
        </geometry>
      </visual>
      <visual name="distribution_box_visual">
      	<pose>4.276 1.25 1.15 1.57 -0 -3.14</pose>
        <geometry>
          <mesh>
            <uri>meshes/distribution.dae</uri>
          </mesh>
        </geometry>
      </visual>
      <visual name="power_box_visual">
      	<pose>4.376 0.45 1.2 1.57 -0 3.14</pose>
        <geometry>
          <mesh>
            <uri>meshes/power.dae</uri>
          </mesh>
        </geometry>
      </visual>
      <visual name="antenna_visual">
      	<pose>4.1 0.25 1.12 1.57 -0 3.14</pose>
        <geometry>
          <mesh>
            <uri>meshes/antenna.dae</uri>
          </mesh>
        </geometry>
      </visual>
      <visual name="left_prop_visual">
      	<pose>4.376 1.135 0.65 1.57 -0 3.14</pose>
        <geometry>
          <mesh>
            <uri>meshes/propeller.dae</uri>
          </mesh>
        </geometry>
      </visual>
      <visual name="right_prop_visual">
      	<pose>4.376 1.85 0.65 1.57 -0 3.14</pose>
        <geometry>
          <mesh>
            <uri>meshes/propeller.dae</uri>
          </mesh>
        </geometry>
      </visual>
      <collision name="base_collision">
      	<pose>2.5 1.45 0.6 0 0 3.14</pose>
        <geometry>
          <mesh>
            <uri>meshes/WAM-V-Base.dae</uri>
          </mesh>
        </geometry>
      </collision>
      <sensor name="imu_sensor" type="imu">
        <always_on>1</always_on>
        <pose>2.5 1.6 0.6 0 0 3.14</pose>
        <update_rate>250</update_rate>
      </sensor>
    </link>
    <link name="ballast_tank">
    	<pose>1.45 0.4 1.07 0 .05 0</pose>
    	<inertial>
        <pose>0 0 0 0 0 0</pose>
        <mass>75</mass>
        <inertia>
          <ixx>1.36125</ixx>
          <ixy>0</ixy>
          <ixz>0</ixz>
          <iyy>6.930625</iyy>
          <iyz>0</iyz>
          <izz>6.930625</izz>
        </inertia>
      </inertial>
    	<visual name="ballast_visual">
    		<pose>-0.55 -0.15 -0.17 1.57 0 1.57</pose>
    		<geometry>
    			<mesh>
            <uri>meshes/ballast.dae</uri>
          </mesh>
    		</geometry>
    	</visual>
    	<collision name="ballast_collision">
    		<geometry>
    			<box>
    				<size>1 .33 .33</size>
    			</box>
    		</geometry>
    	</collision>
    </link>
    <joint name='ballast_joint' type='fixed'>
      <child>ballast_tank</child>
      <parent>base_link</parent>
    </joint>
    
    <link name="airspeed">
      <pose>2.5 1.6 0.6 0 0 3.14</pose>
      <inertial>
        <pose>0 0 0 0 0 0</pose>
        <mass>0.015</mass>
        <inertia>
          <ixx>1e-05</ixx>
          <ixy>0</ixy>
          <ixz>0</ixz>
          <iyy>1e-05</iyy>
          <iyz>0</iyz>
          <izz>1e-05</izz>
        </inertia>
      </inertial>
      <visual name="visual">
        <geometry>
          <cylinder>
            <radius>0.01</radius>
            <length>0.1</length>
          </cylinder>
        </geometry>
        <material>
          <ambient>0 0 0 1.0</ambient>
          <diffuse>0 0 0 1.0</diffuse>
        </material>
      </visual>
      <!-- <sensor name="air_speed" type="air_speed">
        <always_on>1</always_on>
        <update_rate>5.0</update_rate>
        <enable_metrics>false</enable_metrics>
        <air_speed>
          <airspeed>
            <noise type="gaussian">
              <mean>0</mean>
              <stddev>0.01</stddev>
            </noise>
          </airspeed>
        </air_speed>
      </sensor> -->
    </link>
    <joint name='airspeed_joint' type='fixed'>
      <child>airspeed</child>
      <parent>base_link</parent>
    </joint>
    
    <link name="port_hull">
    	<inertial>
        <pose>2.551 2.5 0.6 1.57 -0 0</pose>
        <mass>40</mass>
        <inertia><gravity>1</gravity>
      <self_collide>0</self_collide>
      <kinematic>0</kinematic>
      <enable_wind>1</enable_wind>
          <ixx>1.376</ixx>
          <ixy>0</ixy>
          <ixz>0.078</ixz>
          <iyy>62.554</iyy>
          <iyz>0</iyz>
          <izz>63.146</izz>
        </inertia>
      </inertial>
      <visual name='port_hull_visual'>
        <pose>0.012 0.235 0.25 1.57 -0 0</pose>
        <geometry>
          <mesh>
            <uri>meshes/port.dae</uri>
            <scale>1 1 1</scale>
          </mesh>
        </geometry>
        <material>
          <lighting>1</lighting>
          <script>
            <uri>file://media/materials/scripts/gazebo.material</uri>
            <name>Gazebo/Red</name>
          </script>
          <shader type='pixel'>
            <normal_map>__default__</normal_map>
          </shader>
          <ambient>0.5 0 0 1</ambient>
          <diffuse>0.5 0 0 1</diffuse>
          <specular>0.01 0.01 0.01 1</specular>
          <emissive>0 0 0 1</emissive>
        </material>
        <transparency>0</transparency>
        <cast_shadows>1</cast_shadows>
      </visual>
      <visual name="port_hull_cover_visual">
      	<pose>0 0.23 0.25 1.57 -0 0</pose>
        <geometry>
          <mesh>
            <uri>meshes/port_cover.dae</uri>
          </mesh>
        </geometry>
      </visual>
  		<collision name='port_hull_collision'>
  			<pose>0.012 0.235 0.25 1.57 -0 0</pose>
	      <geometry>
	        <mesh>
	          <uri>meshes/port.dae</uri>
	          <scale>1 1 1</scale>
	        </mesh><gravity>1</gravity>
      <self_collide>0</self_collide>
      <kinematic>0</kinematic>
      <enable_wind>1</enable_wind>
	      </geometry>
	  	</collision>
	  </link>
	  <link name='starboard_hull'>
	  	<inertial>
        <pose>2.551 0.412 0.6 1.57 -0 0</pose>
        <mass>40</mass>
        <inertia>
          <ixx>1.376</ixx>
          <ixy>0</ixy>
          <ixz>0.078</ixz>
          <iyy>62.554</iyy>
          <iyz>0</iyz>
          <izz>63.146</izz>
        </inertia>
      </inertial>
      <visual name='starboard_hull_visual'>
        <pose>-0.002 2.473 0.3 1.57 -0 0</pose>
        <geometry>
          <mesh>
            <uri>meshes/starboard.dae</uri>
            <scale>1 1 1</scale>
          </mesh>
        </geometry>
        <material>
          <lighting>1</lighting>
          <script>
            <uri>file://media/materials/scripts/gazebo.material</uri>
            <name>Gazebo/Red</name>
          </script>
          <shader type='pixel'>
            <normal_map>__default__</normal_map>
          </shader>
          <ambient>0.5 0 0 1</ambient>
          <diffuse>0.5 0 0 1</diffuse>
          <specular>0.01 0.01 0.01 1</specular>
          <emissive>0 0 0 1</emissive>
        </material>
        <transparency>0</transparency>
        <cast_shadows>1</cast_shadows>
      </visual>
      <visual name="starboard_hull_cover_visual">
      	<pose>0 2.45 0.28 1.57 -0 0</pose>
        <geometry>
          <mesh>
            <uri>meshes/starboard_cover.dae</uri>
          </mesh>
        </geometry>
      </visual>
	  	<collision name='starboard_hull_collision'>
  			<pose>-0.002 2.473 0.3 1.57 -0 0</pose>
        <geometry>
          <mesh>
            <uri>meshes/starboard.dae</uri>
            <scale>1 1 1</scale>
          </mesh>
        </geometry>
	  	</collision>
	  </link>
	  
	  <joint name="port_hull_joint" type='fixed'>
	  	<child>port_hull</child>
	  	<parent>base_link</parent>
	  </joint>
	  <joint name="starboard_hull_joint" type='fixed'>
	  	<child>starboard_hull</child>
	  	<parent>base_link</parent>
	  </joint>		
	  
    <link name='rudder_1'>
      <inertial>
        <mass>1</mass>
        <inertia>
          <ixx>0.01</ixx>
          <ixy>0</ixy>
          <ixz>0</ixz>
          <iyy>0.12425</iyy>
          <iyz>0</iyz>
          <izz>0.11475</izz>
        </inertia>
        <pose>0.5 0.015 0.1 0 -0 0</pose>
      </inertial>
      <pose>5.10241 0.426855 0 0.011924 -1.55249 -3.12692</pose>
      <gravity>1</gravity>
      <self_collide>0</self_collide>
      <kinematic>0</kinematic>
      <enable_wind>1</enable_wind>
      <visual name="rudder_1_visual">
      	<pose>0 0 0 0 0 0</pose>
        <geometry>
          <mesh>
            <uri>meshes/rudder.dae</uri>
          </mesh>
        </geometry>
      </visual>
      <collision name='collision'>
        <pose>0 0 0 0 -0 0</pose>
        <geometry>
          <mesh>
            <uri>meshes/rudder.stl</uri>
          </mesh>
        </geometry>
      </collision>
    </link>
    <link name='rudder_2'>
      <inertial>
        <mass>1</mass>
        <inertia>
          <ixx>0.01</ixx>
          <ixy>0</ixy>
          <ixz>0</ixz>
          <iyy>0.12425</iyy>
          <iyz>0</iyz>
          <izz>0.11475</izz>
        </inertia>
        <pose>0.5 0.015 0.1 0 -0 0</pose>
      </inertial>
      <pose>5.1144 2.47458 0 0.011924 -1.55249 -3.12692</pose>
      <gravity>1</gravity>
      <self_collide>0</self_collide>
      <kinematic>0</kinematic>
      <enable_wind>1</enable_wind>
      <visual name="rudder_2_visual">
      	<pose>0 0 0 0 0 0</pose>
        <geometry>
          <mesh>
            <uri>meshes/rudder.dae</uri>
          </mesh>
        </geometry>
      </visual>
      <collision name='collision'>
        <pose>0 0 0 0 -0 0</pose>
        <geometry>
          <mesh>
            <uri>meshes/rudder.stl</uri>
          </mesh>
        </geometry>
      </collision>
    </link>
    
    <joint name='servo_0' type='revolute'>
      <parent>base_link</parent>
      <child>rudder_1</child>
      <pose>0.85 0.02 0 0 -0 0</pose>
      <axis>
        <xyz>1 0 0</xyz>
        <limit>
        	<upper>0.53</upper>
        	<lower>-0.53</lower>
        	<effort>100</effort>
        	<velocity>1</velocity>
        </limit>
        <dynamics>
          <spring_reference>0</spring_reference>
          <spring_stiffness>0</spring_stiffness>
        </dynamics>
      </axis>
    </joint>
    <joint name='servo_1' type='revolute'>
      <parent>base_link</parent>
      <child>rudder_2</child>
      <pose>0.85 0.02 0 0 -0 0</pose>
      <axis>
        <xyz>1 0 0</xyz>
        <limit>
        	<upper>0.53</upper>
        	<lower>-0.53</lower>
        	<effort>100</effort>
        	<velocity>1</velocity>
        </limit>
        <dynamics>
          <spring_reference>0</spring_reference>
          <spring_stiffness>0</spring_stiffness>
        </dynamics>
      </axis>
    </joint>
    
    <!-- plugin filename="gz-sim-lift-drag-system" name="gz::sim::systems::LiftDrag">
      <a0>0</a0>
      <cla>0.1</cla>
      <cda>0</cda>
      <cma>0</cma>
      <alpha_stall>0.261799</alpha_stall>
      <cla_stall>-0.1</cla_stall>
      <cda_stall>0</cda_stall>
      <cma_stall>0</cma_stall>
      <cp>2.1 2.51 4.3</cp>
      <area>21.115</area>
      <air_density>1.29</air_density>
      <forward>-1 0 0</forward>
      <upward>0 0 1</upward>
      <link_name>wing_1</link_name>
      <control_joint_name>base_link_wing_1</control_joint_name>
      <control_joint_rad_to_cl>-1.0</control_joint_rad_to_cl>
    </plugin> -->
    
    <plugin name="gz::sim::systems::SailLiftDrag"
        filename="asv_sim2-sail-lift-drag-system">
      <a0>0.0</a0>
      <cla>5.160550459</cla>
      <alpha_stall>1.0e+308</alpha_stall>
      <cla_stall>5.160550459</cla_stall>
      <!-- <cda>0.63662</cda> -->
      <cda>0.3</cda>
      <cda_stall>0.3</cda_stall>
      <area>0.5</area>
      <fluid_density>1.2</fluid_density>
      <forward>-1 0 0</forward>
      <upward>0 1 0</upward>
      <cp>2.1 2.51 4.3</cp>
      <link_name>wing_1</link_name>
      <radial_symmetry>true</radial_symmetry>
      <topic>lift_drag</topic>
    </plugin>
    
    
    <!-- plugin filename="gz-sim-lift-drag-system" name="gz::sim::systems::LiftDrag">
      <a0>0</a0>
      <cla>0.1</cla>
      <cda>0</cda>
      <cma>0</cma>
      <alpha_stall>0.261799</alpha_stall>
      <cla_stall>-0.1</cla_stall>
      <cda_stall>0</cda_stall>
      <cma_stall>0</cma_stall>
      <cp>4.1 2.51 4.3</cp>
      <area>21.115</area>
      <air_density>1.29</air_density>
      <forward>-1 0 0</forward>
      <upward>0 0 1</upward>
      <link_name>wing_2</link_name>
      <control_joint_name>base_link_wing_2</control_joint_name>
      <control_joint_rad_to_cl>-1.0</control_joint_rad_to_cl>
    </plugin> -->
    
    <!--plugin name="gz::sim::systems::SailLiftDrag"
        filename="asv_sim2-sail-lift-drag-system">
      <a0>0.0</a0>
      <cla>5.160550459</cla>
      <alpha_stall>1.0e+308</alpha_stall>
      <cla_stall>5.160550459</cla_stall>
      <cda>0.3</cda>
      <cda_stall>0.3</cda_stall>
      <area>0.5</area>
      <fluid_density>1.2</fluid_density>
      <forward>-1 0 0</forward>
      <upward>0 1 0</upward>
      <cp>4.1 2.51 4.3</cp>
      <link_name>wing_2</link_name>
      <radial_symmetry>true</radial_symmetry>
      <topic>lift_drag</topic>
    </plugin-->
		
	<plugin filename="gz-sim-lift-drag-system" name="gz::sim::systems::LiftDrag">
      <a0>0</a0>
      <cla>10</cla>
      <cda>10</cda>
      <cma>0.0</cma>
      <alpha_stall>0.5</alpha_stall>
      <cla_stall>-10</cla_stall>
      <cda_stall>10</cda_stall>
      <cma_stall>0</cma_stall>
      <cp>0.5 0.02 0.12</cp>
      <area>3.5</area>
      <air_density>997</air_density>
      <forward>-1 0 0</forward>
      <upward>0 1 0</upward>
      <link_name>rudder_1</link_name>
      <control_joint_name>servo_0</control_joint_name>
    </plugin>
    <plugin
      filename="gz-sim-joint-position-controller-system" name="gz::sim::systems::JointPositionController">
      <joint_name>servo_0</joint_name>
      <sub_topic>servo_0</sub_topic>
      <p_gain>8</p_gain>
      <i_gain>2</i_gain>
      <i_max>1</i_max>
      <i_min>-1</i_min>
      <cmd_max>100</cmd_max>
      <cmd_min>-100</cmd_min>
    </plugin>
    
    
    <plugin filename="gz-sim-lift-drag-system" name="gz::sim::systems::LiftDrag">
      <a0>0</a0>
      <cla>10</cla>
      <cda>10</cda>
      <cma>0.0</cma>
      <alpha_stall>0.5</alpha_stall>
      <cla_stall>-10</cla_stall>
      <cda_stall>10</cda_stall>
      <cma_stall>0</cma_stall>
      <cp>0.5 0.02 0.12</cp>
      <area>3.5</area>
      <air_density>997</air_density>
      <forward>-1 0 0</forward>
      <upward>0 1 0</upward>
      <link_name>rudder_2</link_name>
      <control_joint_name>servo_1</control_joint_name>
    </plugin>
    <plugin
      filename="gz-sim-joint-position-controller-system" name="gz::sim::systems::JointPositionController">
      <joint_name>servo_1</joint_name>
      <sub_topic>servo_1</sub_topic>
      <p_gain>8</p_gain>
      <i_gain>2</i_gain>
      <i_max>1</i_max>
      <i_min>-1</i_min>
      <cmd_max>100</cmd_max>
      <cmd_min>-100</cmd_min>
    </plugin>
    
    <link name='wing_1'>
      <pose>2.47482 2.49991 0.615342 1.57 0 3.14</pose>
      <inertial>
        <pose>.4 3.25 0 0 -0 0</pose>
        <mass>20</mass>
        <inertia>
          <ixx>46.89045</ixx>
          <ixy>0</ixy>
          <ixz>0</ixz>
          <iyy>0.7065</iyy>
          <iyz>0</iyz>
          <izz>47.4867</izz>
        </inertia>
      </inertial>
      <visual name="visual">
      	<pose>0 0.5 0 0 -0 0</pose>
        <geometry>
          <mesh>
            <uri>meshes/wing.dae</uri>
          </mesh>
        </geometry>
      </visual>
      <collision name="collision">
      	<pose>0 0.5 0 0 -0 0</pose>
        <geometry>
          <mesh>
            <uri>meshes/wing.dae</uri>
          </mesh>
        </geometry>
      </collision>
      <visual name="flap_visual">
      	<pose>0 0.5 0 0 -0 0</pose>
        <geometry>
          <mesh>
            <uri>meshes/flap.dae</uri>
          </mesh>
        </geometry>
      </visual>
      <visual name="windvane_visual">
      	<pose>0.295 6.595 0 0 -0 0</pose>
        <geometry>
          <mesh>
            <uri>meshes/windvane.dae</uri>
          </mesh>
        </geometry>
      </visual>
    </link>
    
    <link name='wing_2'>
      <pose>4.51199 2.49807 0.615342 1.57 0 3.14</pose>
      <inertial>
        <pose>.4 3.25 0 0 -0 0</pose>
        <mass>20</mass>
        <inertia>
          <ixx>46.89045</ixx>
          <ixy>0</ixy>
          <ixz>0</ixz>
          <iyy>0.7065</iyy>
          <iyz>0</iyz>
          <izz>47.4867</izz>
        </inertia>
      </inertial>
      <visual name="wing_visual">
      	<pose>0 0.5 0 0 -0 0</pose>
        <geometry>
          <mesh>
            <uri>meshes/wing.dae</uri>
          </mesh>
        </geometry>
      </visual>
      <collision name="collision">
      	<pose>0 0.5 0 0 -0 0</pose>
        <geometry>
          <mesh>
            <uri>meshes/wing.dae</uri>
          </mesh>
        </geometry>
      </collision>
      <visual name="flap_visual">
      	<pose>0 0.5 0 0 -0 0</pose>
        <geometry>
          <mesh>
            <uri>meshes/flap.dae</uri>
          </mesh>
        </geometry>
      </visual>
      <visual name="windvane_visual">
      	<pose>0.295 6.595 0 0 -0 0</pose>
        <geometry>
          <mesh>
            <uri>meshes/windvane.dae</uri>
          </mesh>
        </geometry>
      </visual>
    </link>
    
    <!--  ################## JOINTS ###################### -->
    <joint name='base_link_wing_1' type='revolute'>
      <parent>base_link</parent>
      <child>wing_1</child>
      <pose>0.305 0 0 0 -0 0</pose>
      <axis>
        <xyz>0 1 0</xyz>
        <dynamics>
          <spring_reference>0</spring_reference>
          <spring_stiffness>0</spring_stiffness>
        </dynamics>
      </axis>
    </joint>
    
    <joint name='base_link_wing_2' type='revolute'>
      <parent>base_link</parent>
      <child>wing_2</child>
      <pose>0.305 0 0 0 -0 0</pose>
      <axis>
        <xyz>0 1 0</xyz>
        <dynamics>
          <spring_reference>0</spring_reference>
          <spring_stiffness>0</spring_stiffness>
        </dynamics>
      </axis>
    </joint>
    
    <plugin filename="ignition-gazebo-multicopter-motor-model-system" name="gz::sim::systems::MulticopterMotorModel">
      <jointName>base_link_wing_1</jointName>
      <linkName>wing_1</linkName>
      <turningDirection>cw</turningDirection>
      <timeConstantUp>0.0125</timeConstantUp>
      <timeConstantDown>0.025</timeConstantDown>
      <maxRotVelocity>5</maxRotVelocity>
      <motorConstant>2.44858e-05</motorConstant>
      <momentConstant>0.016</momentConstant>
      <commandSubTopic>command/motor_speed</commandSubTopic>
      <motorNumber>0</motorNumber>
      <rotorDragCoefficient>8.06428e-05</rotorDragCoefficient>
      <rollingMomentCoefficient>1e-06</rollingMomentCoefficient>
      <rotorVelocitySlowdownSim>10</rotorVelocitySlowdownSim>
      <motorType>velocity</motorType>
    </plugin>
    
    <plugin filename="ignition-gazebo-multicopter-motor-model-system" name="gz::sim::systems::MulticopterMotorModel">
      <jointName>base_link_wing_2</jointName>
      <linkName>wing_2</linkName>
      <turningDirection>cw</turningDirection>
      <timeConstantUp>0.0125</timeConstantUp>
      <timeConstantDown>0.025</timeConstantDown>
      <maxRotVelocity>5</maxRotVelocity>
      <motorConstant>2.44858e-05</motorConstant>
      <momentConstant>0.016</momentConstant>
      <commandSubTopic>command/motor_speed</commandSubTopic>
      <motorNumber>1</motorNumber>
      <rotorDragCoefficient>8.06428e-05</rotorDragCoefficient>
      <rollingMomentCoefficient>1e-06</rollingMomentCoefficient>
      <rotorVelocitySlowdownSim>10</rotorVelocitySlowdownSim>
      <motorType>velocity</motorType>
    </plugin>
    
		    <!-- Hydrodynamics plugin -->
		<plugin
		    filename="libgz-waves1-hydrodynamics-system.so"
		    name="gz::sim::systems::Hydrodynamics">
		    
		    <enable>boat_0::base_link</enable>
		    <!--enable>boat_0::port_hull</enable>
		    <enable>boat_0::starboard_hull</enable-->
		    <hydrodynamics>
		      <damping_on>1</damping_on>
		      <viscous_drag_on>1</viscous_drag_on>
		      <pressure_drag_on>1</pressure_drag_on>
		    
		      <!-- Linear and Angular Damping -->
		      <cDampL1>1.0E-6</cDampL1>
		      <cDampL2>1.0E-6</cDampL2>
		      <cDampR1>1.0E-6</cDampR1>
		      <cDampR2>1.0E-6</cDampR2>
		    
		      <!-- 'Pressure' Drag -->
		      <cPDrag1>1.0E+2</cPDrag1>
		      <cPDrag2>1.0E+2</cPDrag2>
		      <fPDrag>0.04</fPDrag>
		      <cSDrag1>1.0E+2</cSDrag1>
		      <cSDrag2>1.0E+2</cSDrag2>
		      <fSDrag>0.04</fSDrag>
		      <vRDrag>1.0</vRDrag>
		    </hydrodynamics>
		</plugin>
  </model>
</sdf>
